Workbook
Name Slicer_Deal_Group: #N/A
Name Slicer_Month: #N/A
Name Slicer_Years: #N/A

Sheet Call Center Dataset
A1: Date | B1: Total Calls | C1: Calls Reached | D1: Average Duration (sec) | E1: Deals Closed | F1: Deal Value ($) | G1: Full Name | H1: Gender | I1: Deal Group | J1: Month | K1: Call Conversion Rate (%) | L1: weekday
A2: 45088 | B2: 81 | C2: 15 | D2: 123.82974 | E2: 6 | F2: 1566.5402 | G2: Noah Rodriguez | H2: Male | I2: Low Volume Deals | J2: =TEXT(Call_Center_Dataset[[#This Row],[Date]],"mmm") -> Jun | K2: =Call_Center_Dataset[[#This Row],[Deals Closed]]/Call_Center_Dataset[[#This Row],[Calls Reached]] -> 0.4 | L2: =TEXT(Call_Center_Dataset[[#This Row],[Date]],"ddd") -> Sun
A3: 45206 | B3: 41 | C3: 18 | D3: 483.18187 | E3: 9 | F3: 4783.5731 | G3: Sophia Garcia | H3: Male | I3: Low Volume Deals | J3: =TEXT(Call_Center_Dataset[[#This Row],[Date]],"mmm") -> Oct | K3: =Call_Center_Dataset[[#This Row],[Deals Closed]]/Call_Center_Dataset[[#This Row],[Calls Reached]] -> 0.5 | L3: =TEXT(Call_Center_Dataset[[#This Row],[Date]],"ddd") -> Sat
A4: 45048 | B4: 38 | C4: 8 | D4: 348.69166 | E4: 3 | F4: 4918.4427 | G4: Noah Davis | H4: Male | I4: Low Volume Deals | J4: =TEXT(Call_Center_Dataset[[#This Row],[Date]],"mmm") -> May | K4: =Call_Center_Dataset[[#This Row],[Deals Closed]]/Call_Center_Dataset[[#This Row],[Calls Reached]] -> 0.375 | L4: =TEXT(Call_Center_Dataset[[#This Row],[Date]],"ddd") -> Tue
A5: 44964 | B5: 24 | C5: 11 | D5: 65.652584 | E5: 7 | F5: 2991.4395 | G5: Emma Rodriguez | H5: Female | I5: Low Volume Deals | J5: =TEXT(Call_Center_Dataset[[#This Row],[Date]],"mmm") -> Feb | K5: =Call_Center_Dataset[[#This Row],[Deals Closed]]/Call_Center_Dataset[[#This Row],[Calls Reached]] -> 0.63636364 | L5: =TEXT(Call_Center_Dataset[[#This Row],[Date]],"ddd") -> Tue
A6: 45079 | B6: 88 | C6: 6 | D6: 392.66566 | E6: 8 | F6: 2642.7392 | G6: Alice Williams | H6: Male | I6: Low Volume Deals | J6: =TEXT(Call_Center_Dataset[[#This Row],[Date]],"mmm") -> Jun | K6: =Call_Center_Dataset[[#This Row],[Deals Closed]]/Call_Center_Dataset[[#This Row],[Calls Reached]] -> 1.3333333 | L6: =TEXT(Call_Center_Dataset[[#This Row],[Date]],"ddd") -> Fri
A7: 45264 | B7: 50 | C7: 20 | D7: 115.96733 | E7: 18 | F7: 727.86995 | G7: Sophia Davis | H7: Female | I7: High Volume Deals | J7: =TEXT(Call_Center_Dataset[[#This Row],[Date]],"mmm") -> Dec | K7: =Call_Center_Dataset[[#This Row],[Deals Closed]]/Call_Center_Dataset[[#This Row],[Calls Reached]] -> 0.9 | L7: =TEXT(Call_Center_Dataset[[#This Row],[Date]],"ddd") -> Mon
A8: 45191 | B8: 59 | C8: 8 | D8: 526.57807 | E8: 5 | F8: 2863.1865 | G8: Liam Martinez | H8: Female | I8: Low Volume Deals | J8: =TEXT(Call_Center_Dataset[[#This Row],[Date]],"mmm") -> Sep | K8: =Call_Center_Dataset[[#This Row],[Deals Closed]]/Call_Center_Dataset[[#This Row],[Calls Reached]] -> 0.625 | L8: =TEXT(Call_Center_Dataset[[#This Row],[Date]],"ddd") -> Fri
A9: 45207 | B9: 37 | C9: 17 | D9: 402.91754 | E9: 9 | F9: 957.04665 | G9: Diana Brown | H9: Male | I9: Low Volume Deals | J9: =TEXT(Call_Center_Dataset[[#This Row],[Date]],"mmm") -> Oct | K9: =Call_Center_Dataset[[#This Row],[Deals Closed]]/Call_Center_Dataset[[#This Row],[Calls Reached]] -> 0.52941176 | L9: =TEXT(Call_Center_Dataset[[#This Row],[Date]],"ddd") -> Sun
A10: 45165 | B10: 59 | C10: 17 | D10: 259.643 | E10: 7 | F10: 4791.2095 | G10: Diana Williams | H10: Female | I10: Low Volume Deals | J10: =TEXT(Call_Center_Dataset[[#This Row],[Date]],"mmm") -> Aug | K10: =Call_Center_Dataset[[#This Row],[Deals Closed]]/Call_Center_Dataset[[#This Row],[Calls Reached]] -> 0.41176471 | L10: =TEXT(Call_Center_Dataset[[#This Row],[Date]],"ddd") -> Sun
A11: 45029 | B11: 34 | C11: 19 | D11: 438.2226 | E11: 7 | F11: 2524.38 | G11: Mason Johnson | H11: Female | I11: Low Volume Deals | J11: =TEXT(Call_Center_Dataset[[#This Row],[Date]],"mmm") -> Apr | K11: =Call_Center_Dataset[[#This Row],[Deals Closed]]/Call_Center_Dataset[[#This Row],[Calls Reached]] -> 0.36842105 | L11: =TEXT(Call_Center_Dataset[[#This Row],[Date]],"ddd") -> Thu
A12: 45019 | B12: 90 | C12: 19 | D12: 439.81879 | E12: 3 | F12: 1011.1833 | G12: Noah Davis | H12: Female | I12: Low Volume Deals | J12: =TEXT(Call_Center_Dataset[[#This Row],[Date]],"mmm") -> Apr | K12: =Call_Center_Dataset[[#This Row],[Deals Closed]]/Call_Center_Dataset[[#This Row],[Calls Reached]] -> 0.15789474 | L12: =TEXT(Call_Center_Dataset[[#This Row],[Date]],"ddd") -> Mon
A13: 45207 | B13: 64 | C13: 6 | D13: 269.53209 | E13: 9 | F13: 2173.794 | G13: Jake Williams | H13: Male | I13: Low Volume Deals | J13: =TEXT(Call_Center_Dataset[[#This Row],[Date]],"mmm") -> Oct | K13: =Call_Center_Dataset[[#This Row],[Deals Closed]]/Call_Center_Dataset[[#This Row],[Calls Reached]] -> 1.5 | L13: =TEXT(Call_Center_Dataset[[#This Row],[Date]],"ddd") -> Sun
... A1066: 45657 | B1066: 75 | C1066: 32 | D1066: 368.55327 | E1066: 39 | F1066: 760.29204 | G1066: John Johnson | H1066: Male | I1066: High Volume Deals | J1066: =TEXT(Call_Center_Dataset[[#This Row],[Date]],"mmm") -> Dec | K1066: =Call_Center_Dataset[[#This Row],[Deals Closed]]/Call_Center_Dataset[[#This Row],[Calls Reached]] -> 1.21875 | L1066: =TEXT(Call_Center_Dataset[[#This Row],[Date]],"ddd") -> Tue

Sheet Table1
A1: Date | B1: Total Calls | C1: Calls Reached | D1: Average Duration (sec) | E1: Deals Closed | F1: Deal Value ($) | G1: First Name | H1: Last Name | I1: Gender
A2: 45292 | B2: 74 | C2: 12 | D2: 330.42 | E2: 7 | F2: 4276.31 | G2: Evan | H2: Garcia | I2: Male
A3: 45292 | B3: 43 | C3: 15 | D3: 363.48 | E3: 7 | F3: 3843.52 | G3: Mimi | H3: Williams | I3: Female
A4: 45292 | B4: 92 | C4: 13 | D4: 422.39 | E4: 1 | F4: 2695.84 | G4: Craig | H4: Martinez | I4: Female
A5: 45292 | B5: 63 | C5: 8 | D5: 170.49 | E5: 7 | F5: 526.12 | G5: Josh | H5: Johnson | I5: Male
A6: 45292 | B6: 96 | C6: 80 | D6: 532.83 | E6: 40 | F6: 3173.13 | G6: Emma | H6: Johnson | I6: Female
A7: 45292 | B7: 100 | C7: 60 | D7: 279.95 | E7: 50 | F7: 1432.23 | G7: Grace | H7: Rodriguez | I7: Male
A8: 45292 | B8: 73 | C8: 12 | D8: 507.45 | E8: 0 | F8: 1123.84 | G8: Vicky | H8: Jones | I8: Male
A9: 45292 | B9: 92 | C9: 20 | D9: 161.42 | E9: 4 | F9: 425.41 | G9: Will | H9: Garcia | I9: Female
A10: 45292 | B10: 31 | C10: 17 | D10: 476.95 | E10: 7 | F10: 3945.43 | G10: Darren | H10: Smith | I10: Female
A11: 45292 | B11: 81 | C11: 7 | D11: 82.43 | E11: 7 | F11: 3463.96 | G11: Karol | H11: Rodriguez | I11: Male
A12: 45292 | B12: 82 | C12: 4 | D12: 180.06 | E12: 4 | F12: 1207.17 | G12: Alex | H12: Williams | I12: Male
A13: 45292 | B13: 54 | C13: 10 | D13: 208.23 | E13: 3 | F13: 645.83 | G13: Melissa | H13: Johnson | I13: Male
... A566: 45657 | B566: 75 | C566: 32 | D566: 368.55327 | E566: 39 | F566: 760.29204 | G566: John | H566: Johnson | I566: Male

Sheet Dashboard

Sheet Analysis
D10: Total Calls | E10: Calls Reached | F10: Deals Closed | G10: Deal Value ($) | H10: Average of Average Duration (sec)
D11: 2261 | E11: 510 | F11: 251 | G11: 83123.667 | H11: 352.2399 | CJ11: 187
CJ12: =CJ11-8 -> 179
P14: Call Reach | AE14: Deal Closed | AU14: Deal Closed
BN16: FALSE | BO16: TRUE | BP16: TRUE | BQ16: FALSE | CH16: 7
D17: Month | E17: Total Calls | G17: Month | H17: Find position | P17: Month | Q17: Calls Reached | U17: Month | V17: Find position | AE17: Month | AF17: Deals Closed | AJ17: Month | AK17: Find position | AU17: Month | AV17: Deal Value ($) | AZ17: Month | BA17: Find position | BI17: Month | BJ17: Average of Call Conversion Rate (%) | BM17: Month | BN17: Total Calls | BO17: Calls Reached | BP17: Deals Closed | BQ17: Deal Value ($) | BU17: Deal Group | BV17: Count of Deal Group | BY17: Full Name | BZ17: Total Calls | CA17: Calls Reached | CB17: Deals Closed | CC17: Deal Value ($) | CH17: =BY17 -> Full Name | CI17: =BZ17 -> Total Calls | CJ17: =CA17 -> Calls Reached | CK17: =CB17 -> Deals Closed | CL17: =CC17 -> Deal Value ($)
C18: 1 | D18: Jan | E18: 1637 | G18: Jul | H18: =MATCH(G18,D18:D29,0)-1 -> 6 | O18: 1 | P18: Jan | Q18: 389 | U18: Jul | V18: =MATCH(U18,P18:P29,0)-1 -> 6 | AD18: 1 | AE18: Jan | AF18: 161 | AJ18: Jul | AK18: =MATCH(AJ18,AE18:AE29,0)-1 -> 6 | AT18: 1 | AU18: Jan | AV18: 81847.848 | AZ18: Jul | BA18: =MATCH(AZ18,AU18:AU29,0)-1 -> 6 | BI18: Jan | BJ18: #DIV/0! | BM18: Jan | BN18: 1637 | BO18: 389 | BP18: 161 | BQ18: 81847.848 | BU18: High Volume Deals | BV18: 5 | BY18: Mason Miller | BZ18: 143 | CA18: 21 | CB18: 10 | CC18: 5651.8985 | CG18: =IF(CI18>0,1,0) -> 1 | CH18: {=OFFSET(BY17,$CH$16,,)} -> Alice Davis | CI18: {=OFFSET(BZ17,$CH$16,,)} -> 48 | CJ18: {=OFFSET(CA17,$CH$16,,)} -> 10 | CK18: {=OFFSET(CB17,$CH$16,,)} -> 3 | CL18: {=OFFSET(CC17,$CH$16,,)} -> 3695.2804
C19: 2 | D19: Feb | E19: 2174 | F19: =E19-E18 -> 537 | O19: 2 | P19: Feb | Q19: 431 | AD19: 2 | AE19: Feb | AF19: 185 | AT19: 2 | AU19: Feb | AV19: 113982.63 | BI19: Feb | BJ19: 0.51003125 | BM19: Feb | BN19: 2174 | BO19: 431 | BP19: 185 | BQ19: 113982.63 | BU19: Low Volume Deals | BV19: 452 | BY19: Diana Garcia | BZ19: 151 | CA19: 26 | CB19: 13 | CC19: 4664.1004 | CG19: =IF(CI19>0,1,0) -> 1 | CH19: {=OFFSET(BY18,$CH$16,,)} -> Liam Smith | CI19: {=OFFSET(BZ18,$CH$16,,)} -> 53 | CJ19: {=OFFSET(CA18,$CH$16,,)} -> 13 | CK19: {=OFFSET(CB18,$CH$16,,)} -> 9 | CL19: {=OFFSET(CC18,$CH$16,,)} -> 3684.3318
C20: 3 | D20: Mar | E20: 2352 | G20: Previous | O20: 3 | P20: Mar | Q20: 443 | U20: Previous | AD20: 3 | AE20: Mar | AF20: 178 | AJ20: Previous | AT20: 3 | AU20: Mar | AV20: 98025.263 | AZ20: Previous | BI20: Mar | BJ20: 0.44861188 | BM20: Mar | BN20: 2352 | BO20: 443 | BP20: 178 | BQ20: 98025.263 | BU20: No Deals | BV20: 43 | BY20: Emma Williams | BZ20: 55 | CA20: 15 | CB20: 7 | CC20: 4385.9176 | CG20: =IF(CI20>0,1,0) -> 1 | CH20: {=OFFSET(BY19,$CH$16,,)} -> Diana Johnson | CI20: {=OFFSET(BZ19,$CH$16,,)} -> 53 | CJ20: {=OFFSET(CA19,$CH$16,,)} -> 17 | CK20: {=OFFSET(CB19,$CH$16,,)} -> 2 | CL20: {=OFFSET(CC19,$CH$16,,)} -> 3165.3162
C21: 4 | D21: Apr | E21: 2518 | G21: =IFERROR(VLOOKUP(H18,C18:E29,2,0),0) -> Jun | H21: =IFERROR(VLOOKUP(H18,C18:E29,3,0),0) -> 2806 | O21: 4 | P21: Apr | Q21: 537 | U21: =IFERROR(VLOOKUP(V18,O18:Q29,2,0),0) -> Jun | V21: =IFERROR(VLOOKUP(V18,O18:Q29,3,0),0) -> 612 | AD21: 4 | AE21: Apr | AF21: 236 | AJ21: =IFERROR(VLOOKUP(AK18,AD18:AF29,2,0),0) -> Jun | AK21: =IFERROR(VLOOKUP(AK18,AD18:AF29,3,0),0) -> 253 | AT21: 4 | AU21: Apr | AV21: 135080.16 | AZ21: =IFERROR(VLOOKUP(BA18,AT18:AV29,2,0),0) -> Jun | BA21: =IFERROR(VLOOKUP(BA18,AT18:AV29,3,0),0) -> 131891.88 | BI21: Apr | BJ21: 0.49610934 | BM21: Apr | BN21: 2518 | BO21: 537 | BP21: 236 | BQ21: 135080.16 | BY21: Emma Smith | BZ21: 26 | CA21: 16 | CB21: 6 | CC21: 4217.324 | CG21: =IF(CI21>0,1,0) -> 1 | CH21: {=OFFSET(BY20,$CH$16,,)} -> Jake Rodriguez | CI21: {=OFFSET(BZ20,$CH$16,,)} -> 85 | CJ21: {=OFFSET(CA20,$CH$16,,)} -> 9 | CK21: {=OFFSET(CB20,$CH$16,,)} -> 4 | CL21: {=OFFSET(CC20,$CH$16,,)} -> 3149.3022
C22: 5 | D22: May | E22: 2507 | O22: 5 | P22: May | Q22: 535 | AD22: 5 | AE22: May | AF22: 211 | AT22: 5 | AU22: May | AV22: 137203.03 | BI22: May | BJ22: 0.44410955 | BM22: May | BN22: 2507 | BO22: 535 | BP22: 211 | BQ22: 137203.03 | BY22: Diana Smith | BZ22: 32 | CA22: 8 | CB22: 3 | CC22: 4001.0556 | CG22: =IF(CI22>0,1,0) -> 1 | CH22: {=OFFSET(BY21,$CH$16,,)} -> Jake Davis | CI22: {=OFFSET(BZ21,$CH$16,,)} -> 141 | CJ22: {=OFFSET(CA21,$CH$16,,)} -> 29 | CK22: {=OFFSET(CB21,$CH$16,,)} -> 9 | CL22: {=OFFSET(CC21,$CH$16,,)} -> 3016.1822
C23: 6 | D23: Jun | E23: 2806 | O23: 6 | P23: Jun | Q23: 612 | AD23: 6 | AE23: Jun | AF23: 253 | AT23: 6 | AU23: Jun | AV23: 131891.88 | BI23: Jun | BJ23: 0.48811216 | BM23: Jun | BN23: 2806 | BO23: 612 | BP23: 253 | BQ23: 131891.88 | BY23: Diana Miller | BZ23: 69 | CA23: 10 | CB23: 7 | CC23: 3787.797 | CG23: =IF(CI23>0,1,0) -> 1 | CH23: {=OFFSET(BY22,$CH$16,,)} -> Liam Williams | CI23: {=OFFSET(BZ22,$CH$16,,)} -> 80 | CJ23: {=OFFSET(CA22,$CH$16,,)} -> 7 | CK23: {=OFFSET(CB22,$CH$16,,)} -> 6 | CL23: {=OFFSET(CC22,$CH$16,,)} -> 2485.9354
C24: 7 | D24: Jul | E24: 2261 | G24: Current | H24: =D11 -> 2261 | O24: 7 | P24: Jul | Q24: 510 | U24: Current | V24: =$E$11 -> 510 | AD24: 7 | AE24: Jul | AF24: 251 | AJ24: Current | AK24: =$F$11 -> 251 | AT24: 7 | AU24: Jul | AV24: 83123.667 | AZ24: Current | BA24: =$G$11 -> 83123.667 | BI24: Jul | BJ24: 0.45710615 | BM24: Jul | BN24: 2261 | BO24: 510 | BP24: 251 | BQ24: 83123.667 | BY24: Alice Davis | BZ24: 48 | CA24: 10 | CB24: 3 | CC24: 3695.2804 | CG24: =IF(CI24>0,1,0) -> 1 | CH24: {=OFFSET(BY23,$CH$16,,)} -> Evan Miller | CI24: {=OFFSET(BZ23,$CH$16,,)} -> 27 | CJ24: {=OFFSET(CA23,$CH$16,,)} -> 17 | CK24: {=OFFSET(CB23,$CH$16,,)} -> 1 | CL24: {=OFFSET(CC23,$CH$16,,)} -> 2451.8111
C25: 8 | D25: Aug | E25: 3127 | O25: 8 | P25: Aug | Q25: 722 | AD25: 8 | AE25: Aug | AF25: 339 | AT25: 8 | AU25: Aug | AV25: 139005.71 | BI25: Aug | BJ25: 0.49155476 | BM25: Aug | BN25: 3127 | BO25: 722 | BP25: 339 | BQ25: 139005.71 | BY25: Liam Smith | BZ25: 53 | CA25: 13 | CB25: 9 | CC25: 3684.3318 | CG25: =IF(CI25>0,1,0) -> 1 | CH25: {=OFFSET(BY24,$CH$16,,)} -> Sophia Johnson | CI25: {=OFFSET(BZ24,$CH$16,,)} -> 97 | CJ25: {=OFFSET(CA24,$CH$16,,)} -> 16 | CK25: {=OFFSET(CB24,$CH$16,,)} -> 1 | CL25: {=OFFSET(CC24,$CH$16,,)} -> 2153.4267
C26: 9 | D26: Sep | E26: 2955 | H26: =H24-H21 -> -545 | O26: 9 | P26: Sep | Q26: 701 | V26: =V24-V21 -> -102 | AD26: 9 | AE26: Sep | AF26: 371 | AK26: =AK24-AK21 -> -2 | AM26: =AK260=0 -> TRUE | AT26: 9 | AU26: Sep | AV26: 123996.93 | BA26: =BA24-BA21 -> -48768.215 | BI26: Sep | BJ26: 0.5625181 | BM26: Sep | BN26: 2955 | BO26: 701 | BP26: 371 | BQ26: 123996.93 | BY26: Diana Johnson | BZ26: 53 | CA26: 17 | CB26: 2 | CC26: 3165.3162
C27: 10 | D27: Oct | E27: 2947 | H27: =IF(H21=0,0,(H24-H21)/H21) -> -0.19422666 | O27: 10 | P27: Oct | Q27: 621 | V27: =IF(V21=0,0,(V24-V21)/V21) -> -0.16666667 | AD27: 10 | AE27: Oct | AF27: 253 | AK27: =IF(AK21=0,0,(AK24-AK21)/AK21) -> -0.0079051383 | AT27: 10 | AU27: Oct | AV27: 129654.34 | BA27: =IF(BA21=0,0,(BA24-BA21)/BA21) -> -0.36975904 | BI27: Oct | BJ27: 0.50864723 | BM27: Oct | BN27: 2947 | BO27: 621 | BP27: 253 | BQ27: 129654.34 | BY27: Jake Rodriguez | BZ27: 85 | CA27: 9 | CB27: 4 | CC27: 3149.3022
C28: 11 | D28: Nov | E28: 2318 | O28: 11 | P28: Nov | Q28: 488 | AD28: 11 | AE28: Nov | AF28: 205 | AT28: 11 | AU28: Nov | AV28: 109383.09 | BI28: Nov | BJ28: #DIV/0! | BM28: Nov | BN28: 2318 | BO28: 488 | BP28: 205 | BQ28: 109383.09 | BY28: Jake Davis | BZ28: 141 | CA28: 29 | CB28: 9 | CC28: 3016.1822
C29: 12 | D29: Dec | E29: 3052 | G29: Pct | H29: =IF(H27>0,"+"&TEXT(H27,"0.0%"),TEXT(H27,"0.0%")) -> -19.4% | O29: 12 | P29: Dec | Q29: 611 | U29: Pct | V29: =IF(V27>0,"+"&TEXT(V27,"0.0%"),TEXT(V27,"0.0%")) -> -16.7% | AD29: 12 | AE29: Dec | AF29: 261 | AJ29: Pct | AK29: =IF(AK27>0,"+"&TEXT(AK27,"0.0%"),TEXT(AK27,"0.0%")) -> -0.8% | AT29: 12 | AU29: Dec | AV29: 127289.84 | AZ29: Pct | BA29: =IF(BA27>0,"+"&TEXT(BA27,"0.0%"),TEXT(BA27,"0.0%")) -> -37.0% | BI29: Dec | BJ29: 0.48451739 | BM29: Dec | BN29: 3052 | BO29: 611 | BP29: 261 | BQ29: 127289.84 | BY29: Liam Williams | BZ29: 80 | CA29: 7 | CB29: 6 | CC29: 2485.9354
G30: values | H30: =IF(H26>0,"+"&TEXT(H26,"#,##"),H26) -> -545 | K30: Combine | L30: =H29&" | "&H30 -> -19.4% | -545 | U30: values | V30: =IF(V26>0,"+"&TEXT(V26,"#,##"),V26) -> -102 | Y30: Combine | Z30: =V29&" | "&V30 -> -16.7% | -102 | AJ30: values | AK30: =IF(AK26>0,"+"&TEXT(AK26,"#,#"),AK26) -> -2 | AN30: Combine | AO30: =AK29&" | "&AK30 -> -0.8% | -2 | AZ30: values | BA30: =IF(BA26>0,"+"&TEXT(BA26,"#,#"),TEXT(BA26,"#,##")) -> -48,768 | BD30: Combine | BE30: =BA29&" | "&BA30 -> -37.0% | -48,768 | BY30: Evan Miller | BZ30: 27 | CA30: 17 | CB30: 1 | CC30: 2451.8111 | CH30: =IF(SUM(CG18:CG25)=0,"No Data for the Selected Filter",IF(SUM(CG18:CG25)<8,"Scroll back to access more values from earlier"," "))
E31: =SUM(E18:E29) -> 30654 | Q31: =SUM(Q18:Q29) -> 6600 | AF31: =SUM(AF18:AF29) -> 2904 | AV31: =SUM(AV18:AV29) -> 1410484.4 | BY31: Sophia Johnson | BZ31: 97 | CA31: 16 | CB31: 1 | CC31: 2153.4267
BM32: =BM17 -> Month | BN32: =BN17 -> Total Calls | BO32: =BO17 -> Calls Reached | BP32: =BP17 -> Deals Closed | BQ32: =BQ17 -> Deal Value ($) | BY32: Mason Smith | BZ32: 47 | CA32: 12 | CB32: 1 | CC32: 2023.6177
BM33: =BM18 -> Jan | BN33: =IF(BN$16=TRUE,BN18,"") | BO33: =IF(BO$16=TRUE,BO18,"") -> 389 | BP33: =IF(BP$16=TRUE,BP18,"") -> 161 | BQ33: =IF(BQ$16=TRUE,BQ18,"") | BY33: Alice Rodriguez | BZ33: 65 | CA33: 20 | CB33: 7 | CC33: 2014.4349
AK34: 0.0001 | BM34: =BM19 -> Feb | BN34: =IF(BN$16=TRUE,BN19,"") | BO34: =IF(BO$16=TRUE,BO19,"") -> 431 | BP34: =IF(BP$16=TRUE,BP19,"") -> 185 | BQ34: =IF(BQ$16=TRUE,BQ19,"") | BY34: Evan Jones | BZ34: 74 | CA34: 8 | CB34: 1 | CC34: 1917.3104
BM35: =BM20 -> Mar | BN35: =IF(BN$16=TRUE,BN20,"") | BO35: =IF(BO$16=TRUE,BO20,"") -> 443 | BP35: =IF(BP$16=TRUE,BP20,"") -> 178 | BQ35: =IF(BQ$16=TRUE,BQ20,"") | BY35: Diana Martinez | BZ35: 68 | CA35: 5 | CB35: 6 | CC35: 1524.3042
BM36: =BM21 -> Apr | BN36: =IF(BN$16=TRUE,BN21,"") | BO36: =IF(BO$16=TRUE,BO21,"") -> 537 | BP36: =IF(BP$16=TRUE,BP21,"") -> 236 | BQ36: =IF(BQ$16=TRUE,BQ21,"") | BY36: Diana Brown | BZ36: 79 | CA36: 8 | CB36: 7 | CC36: 1333.796
BM37: =BM22 -> May | BN37: =IF(BN$16=TRUE,BN22,"") | BO37: =IF(BO$16=TRUE,BO22,"") -> 535 | BP37: =IF(BP$16=TRUE,BP22,"") -> 211 | BQ37: =IF(BQ$16=TRUE,BQ22,"") | BY37: Noah Jones | BZ37: 20 | CA37: 10 | CB37: 7 | CC37: 1274.2522
AK38: =AK27<AK34 -> TRUE | BM38: =BM23 -> Jun | BN38: =IF(BN$16=TRUE,BN23,"") | BO38: =IF(BO$16=TRUE,BO23,"") -> 612 | BP38: =IF(BP$16=TRUE,BP23,"") -> 253 | BQ38: =IF(BQ$16=TRUE,BQ23,"") | BY38: Diana Davis | BZ38: 77 | CA38: 18 | CB38: 7 | CC38: 924.45648
AK39: =AK27>AK34 -> FALSE | BM39: =BM24 -> Jul | BN39: =IF(BN$16=TRUE,BN24,"") | BO39: =IF(BO$16=TRUE,BO24,"") -> 510 | BP39: =IF(BP$16=TRUE,BP24,"") -> 251 | BQ39: =IF(BQ$16=TRUE,BQ24,"") | BY39: Mason Martinez | BZ39: 94 | CA39: 20 | CB39: 4 | CC39: 909.75817
BM40: =BM25 -> Aug | BN40: =IF(BN$16=TRUE,BN25,"") | BO40: =IF(BO$16=TRUE,BO25,"") -> 722 | BP40: =IF(BP$16=TRUE,BP25,"") -> 339 | BQ40: =IF(BQ$16=TRUE,BQ25,"") | BY40: Sophia Jones | BZ40: 82 | CA40: 12 | CB40: 4 | CC40: 895.66623
BM41: =BM26 -> Sep | BN41: =IF(BN$16=TRUE,BN26,"") | BO41: =IF(BO$16=TRUE,BO26,"") -> 701 | BP41: =IF(BP$16=TRUE,BP26,"") -> 371 | BQ41: =IF(BQ$16=TRUE,BQ26,"") | BY41: Emma Jones | BZ41: 66 | CA41: 12 | CB41: 7 | CC41: 734.89208
BM42: =BM27 -> Oct | BN42: =IF(BN$16=TRUE,BN27,"") | BO42: =IF(BO$16=TRUE,BO27,"") -> 621 | BP42: =IF(BP$16=TRUE,BP27,"") -> 253 | BQ42: =IF(BQ$16=TRUE,BQ27,"") | BY42: Jake Martinez | BZ42: 67 | CA42: 18 | CB42: 3 | CC42: 663.0255
BM43: =BM28 -> Nov | BN43: =IF(BN$16=TRUE,BN28,"") | BO43: =IF(BO$16=TRUE,BO28,"") -> 488 | BP43: =IF(BP$16=TRUE,BP28,"") -> 205 | BQ43: =IF(BQ$16=TRUE,BQ28,"") | BY43: Jake Miller | BZ43: 34 | CA43: 8 | CB43: 7 | CC43: 570.30283
BM44: =BM29 -> Dec | BN44: =IF(BN$16=TRUE,BN29,"") | BO44: =IF(BO$16=TRUE,BO29,"") -> 611 | BP44: =IF(BP$16=TRUE,BP29,"") -> 261 | BQ44: =IF(BQ$16=TRUE,BQ29,"") | BY44: Emma Martinez | BZ44: 22 | CA44: 6 | CB44: 9 | CC44: 542.20748
BN52: TRUE | BO52: TRUE | BP52: FALSE | BQ52: FALSE
BM53: Quarters | BN53: Total Calls | BO53: Calls Reached | BP53: Deals Closed | BQ53: Deal Value ($)
BM54: Qtr1 | BN54: 6163 | BO54: 1263 | BP54: 524 | BQ54: 293855.74
BM55: Qtr2 | BN55: 7831 | BO55: 1684 | BP55: 700 | BQ55: 404175.07
BM56: Qtr3 | BN56: 8343 | BO56: 1933 | BP56: 961 | BQ56: 346126.31
BM57: Qtr4 | BN57: 8317 | BO57: 1720 | BP57: 719 | BQ57: 366327.26
BM68: =BM53 -> Quarters | BN68: =BN53 -> Total Calls | BO68: =BO53 -> Calls Reached | BP68: =BP53 -> Deals Closed | BQ68: =BQ53 -> Deal Value ($)
...

Sheet Sheet4
E8: =Analysis!CH17 -> Full Name | F8: =Analysis!CI17 -> Total Calls | G8: =Analysis!CJ17 -> Calls Reached | H8: =Analysis!CK17 -> Deals Closed | I8: =Analysis!CL17 -> Deal Value ($)
E9: =Analysis!CH18 -> Alice Davis | F9: =Analysis!CI18 -> 48 | G9: =Analysis!CJ18 -> 10 | H9: =Analysis!CK18 -> 3 | I9: =Analysis!CL18 -> 3695.2804
E10: =Analysis!CH19 -> Liam Smith | F10: =Analysis!CI19 -> 53 | G10: =Analysis!CJ19 -> 13 | H10: =Analysis!CK19 -> 9 | I10: =Analysis!CL19 -> 3684.3318
E11: =Analysis!CH20 -> Diana Johnson | F11: =Analysis!CI20 -> 53 | G11: =Analysis!CJ20 -> 17 | H11: =Analysis!CK20 -> 2 | I11: =Analysis!CL20 -> 3165.3162
E12: =Analysis!CH21 -> Jake Rodriguez | F12: =Analysis!CI21 -> 85 | G12: =Analysis!CJ21 -> 9 | H12: =Analysis!CK21 -> 4 | I12: =Analysis!CL21 -> 3149.3022
E13: =Analysis!CH22 -> Jake Davis | F13: =Analysis!CI22 -> 141 | G13: =Analysis!CJ22 -> 29 | H13: =Analysis!CK22 -> 9 | I13: =Analysis!CL22 -> 3016.1822
E14: =Analysis!CH23 -> Liam Williams | F14: =Analysis!CI23 -> 80 | G14: =Analysis!CJ23 -> 7 | H14: =Analysis!CK23 -> 6 | I14: =Analysis!CL23 -> 2485.9354
E15: =Analysis!CH24 -> Evan Miller | F15: =Analysis!CI24 -> 27 | G15: =Analysis!CJ24 -> 17 | H15: =Analysis!CK24 -> 1 | I15: =Analysis!CL24 -> 2451.8111
E16: =Analysis!CH25 -> Sophia Johnson | F16: =Analysis!CI25 -> 97 | G16: =Analysis!CJ25 -> 16 | H16: =Analysis!CK25 -> 1 | I16: =Analysis!CL25 -> 2153.4267
